<?xml version="1.0" encoding="utf-8"?>
<!-- This URDF was automatically created by SolidWorks to URDF Exporter! Originally created by Stephen Brawner (brawner@gmail.com) 
     Commit Version: 1.6.0-4-g7f85cfe  Build Version: 1.6.7995.38578
     For more information, please see http://wiki.ros.org/sw_urdf_exporter -->
<robot
  name="2024.11.15_URDF_ARM">
  <link
    name="base_link">
    <inertial>
      <origin
        xyz="0.026767 -0.01554 0.075"
        rpy="0 0 0" />
      <mass
        value="0.1883" />
      <inertia
        ixx="0.00029329"
        ixy="-3.3956E-05"
        ixz="-2.6337E-09"
        iyy="0.0005445"
        iyz="7.9205E-10"
        izz="0.0003719" />
    </inertial>
    <visual>
      <origin
        xyz="0 0 0"
        rpy="0 0 0" />
      <geometry>
        <mesh
          filename="package://2024.11.15_URDF_ARM/meshes/base_link.STL" />
      </geometry>
      <material
        name="">
        <color
          rgba="0.75294 0.75294 0.75294 1" />
      </material>
    </visual>
    <collision>
      <origin
        xyz="0 0 0"
        rpy="0 0 0" />
      <geometry>
        <mesh
          filename="package://2024.11.15_URDF_ARM/meshes/base_link.STL" />
      </geometry>
    </collision>
  </link>
  <joint
    name="gaxis_joint"
    type="continuous">
    <origin
      xyz="0 0.015943 0"
      rpy="-1.5708 0.4615 0" />
    <parent
      link="4axis_link" />
    <child
      link="gaxis_link" />
    <axis
      xyz="0 0 1" />
  </joint>
  <link
    name="1axis_link">
    <inertial>
      <origin
        xyz="0.046824 0.056719 -0.00011125"
        rpy="0 0 0" />
      <mass
        value="0.28445" />
      <inertia
        ixx="0.00025925"
        ixy="-6.7497E-05"
        ixz="-3.128E-05"
        iyy="0.0003931"
        iyz="-1.6686E-05"
        izz="0.00041221" />
    </inertial>
    <visual>
      <origin
        xyz="0 0 0"
        rpy="0 0 0" />
      <geometry>
        <mesh
          filename="package://2024.11.15_URDF_ARM/meshes/1axis_link.STL" />
      </geometry>
      <material
        name="">
        <color
          rgba="0.75294 0.75294 0.75294 1" />
      </material>
    </visual>
    <collision>
      <origin
        xyz="0 0 0"
        rpy="0 0 0" />
      <geometry>
        <mesh
          filename="package://2024.11.15_URDF_ARM/meshes/1axis_link.STL" />
      </geometry>
    </collision>
  </link>
  <joint
    name="1axis_joint"
    type="continuous">
    <origin
      xyz="0.021569 -0.075 0.0059633"
      rpy="1.5708 0 -0.044547" />
    <parent
      link="base_link" />
    <child
      link="1axis_link" />
    <axis
      xyz="0 1 0" />
  </joint>
  <link
    name="2axis_link">
    <inertial>
      <origin
        xyz="-1.422E-05 0.093446 0.014601"
        rpy="0 0 0" />
      <mass
        value="0.073569" />
      <inertia
        ixx="9.8797E-05"
        ixy="1.5389E-09"
        ixz="1.7293E-09"
        iyy="1.3489E-05"
        iyz="-9.0486E-06"
        izz="9.6869E-05" />
    </inertial>
    <visual>
      <origin
        xyz="0 0 0"
        rpy="0 0 0" />
      <geometry>
        <mesh
          filename="package://2024.11.15_URDF_ARM/meshes/2axis_link.STL" />
      </geometry>
      <material
        name="">
        <color
          rgba="0.75294 0.75294 0.75294 1" />
      </material>
    </visual>
    <collision>
      <origin
        xyz="0 0 0"
        rpy="0 0 0" />
      <geometry>
        <mesh
          filename="package://2024.11.15_URDF_ARM/meshes/2axis_link.STL" />
      </geometry>
    </collision>
  </link>
  <joint
    name="2axis_joint"
    type="continuous">
    <origin
      xyz="0.0885000000000002 0.0975000000000002 0"
      rpy="0 0 -1.53783267944349" />
    <parent
      link="1axis_link" />
    <child
      link="2axis_link" />
    <axis
      xyz="0 0 1" />
  </joint>
  <link
    name="3axis_link">
    <inertial>
      <origin
        xyz="-1.2327E-05 0.090233 0.02885"
        rpy="0 0 0" />
      <mass
        value="0.068878" />
      <inertia
        ixx="7.7092E-05"
        ixy="-2.3898E-09"
        ixz="4.585E-09"
        iyy="1.3674E-05"
        iyz="-1.1011E-05"
        izz="7.4218E-05" />
    </inertial>
    <visual>
      <origin
        xyz="0 0 0"
        rpy="0 0 0" />
      <geometry>
        <mesh
          filename="package://2024.11.15_URDF_ARM/meshes/3axis_link.STL" />
      </geometry>
      <material
        name="">
        <color
          rgba="0.75294 0.75294 0.75294 1" />
      </material>
    </visual>
    <collision>
      <origin
        xyz="0 0 0"
        rpy="0 0 0" />
      <geometry>
        <mesh
          filename="package://2024.11.15_URDF_ARM/meshes/3axis_link.STL" />
      </geometry>
    </collision>
  </link>
  <joint
    name="3axis_joint"
    type="continuous">
    <origin
      xyz="0 0.13 0"
      rpy="-3.14159265358979 0 -1.97319683591892" />
    <parent
      link="2axis_link" />
    <child
      link="3axis_link" />
    <axis
      xyz="0 0 1" />
  </joint>
  <link
    name="4axis_link">
    <inertial>
      <origin
        xyz="0.002003 0.0344 0.00014231"
        rpy="0 0 0" />
      <mass
        value="0.028802" />
      <inertia
        ixx="4.9993E-06"
        ixy="-1.0622E-07"
        ixz="7.2923E-10"
        iyy="3.7249E-06"
        iyz="-1.7557E-07"
        izz="6.4583E-06" />
    </inertial>
    <visual>
      <origin
        xyz="0 0 0"
        rpy="0 0 0" />
      <geometry>
        <mesh
          filename="package://2024.11.15_URDF_ARM/meshes/4axis_link.STL" />
      </geometry>
      <material
        name="">
        <color
          rgba="0.75294 0.75294 0.75294 1" />
      </material>
    </visual>
    <collision>
      <origin
        xyz="0 0 0"
        rpy="0 0 0" />
      <geometry>
        <mesh
          filename="package://2024.11.15_URDF_ARM/meshes/4axis_link.STL" />
      </geometry>
    </collision>
  </link>
  <joint
    name="4axis_joint"
    type="continuous">
    <origin
      xyz="0 0.120000000000001 0"
      rpy="-3.14159265358979 0 -2.78551620311611" />
    <parent
      link="3axis_link" />
    <child
      link="4axis_link" />
    <axis
      xyz="0 0 1" />
  </joint>
  <link
    name="gaxis_link">
    <inertial>
      <origin
        xyz="-0.0024553 -0.00048053 0.1057"
        rpy="0 0 0" />
      <mass
        value="0.095441" />
      <inertia
        ixx="2.4484E-05"
        ixy="6.3221E-07"
        ixz="-9.197E-07"
        iyy="2.9284E-05"
        iyz="-1.2218E-06"
        izz="3.871E-05" />
    </inertial>
    <visual>
      <origin
        xyz="0 0 0"
        rpy="0 0 0" />
      <geometry>
        <mesh
          filename="package://2024.11.15_URDF_ARM/meshes/gaxis_link.STL" />
      </geometry>
      <material
        name="">
        <color
          rgba="0.75294 0.75294 0.75294 1" />
      </material>
    </visual>
    <collision>
      <origin
        xyz="0 0 0"
        rpy="0 0 0" />
      <geometry>
        <mesh
          filename="package://2024.11.15_URDF_ARM/meshes/gaxis_link.STL" />
      </geometry>
    </collision>
  </link>
  <joint
    name="gaxis_joint"
    type="continuous">
    <origin
      xyz="0 0.015943 0"
      rpy="-1.5708 0.4615 0" />
    <parent
      link="4axis_link" />
    <child
      link="gaxis_link" />
    <axis
      xyz="0 0 1" />
  </joint>
</robot>